2021-04-11 10:05:54,857 INFO: DayBalance startup [in /home/bladner/Git/DayBalance/app/__init__.py:31]
2021-04-11 10:07:15,629 INFO: DayBalance startup [in /home/bladner/Git/DayBalance/app/__init__.py:31]
2021-04-11 10:07:34,062 INFO: DayBalance startup [in /home/bladner/Git/DayBalance/app/__init__.py:31]
2021-04-11 10:10:25,885 INFO: DayBalance startup [in /home/bladner/Git/DayBalance/app/__init__.py:31]
2021-04-11 10:11:06,397 INFO: DayBalance startup [in /home/bladner/Git/DayBalance/app/__init__.py:31]
2021-04-11 10:11:49,279 INFO: DayBalance startup [in /home/bladner/Git/DayBalance/app/__init__.py:31]
2021-04-11 10:12:15,383 INFO: DayBalance startup [in /home/bladner/Git/DayBalance/app/__init__.py:31]
2021-04-11 10:13:00,997 INFO: DayBalance startup [in /home/bladner/Git/DayBalance/app/__init__.py:31]
2021-04-11 10:13:12,885 INFO: DayBalance startup [in /home/bladner/Git/DayBalance/app/__init__.py:31]
2021-04-11 10:13:22,419 INFO: DayBalance startup [in /home/bladner/Git/DayBalance/app/__init__.py:31]
2021-04-11 10:14:34,321 INFO: DayBalance startup [in /home/bladner/Git/DayBalance/app/__init__.py:31]
2021-04-11 10:14:40,369 INFO: DayBalance startup [in /home/bladner/Git/DayBalance/app/__init__.py:31]
2021-04-11 10:15:11,195 INFO: DayBalance startup [in /home/bladner/Git/DayBalance/app/__init__.py:31]
2021-04-11 10:16:09,936 INFO: DayBalance startup [in /home/bladner/Git/DayBalance/app/__init__.py:31]
2021-04-11 10:16:23,562 ERROR: Exception on / [GET] [in /home/bladner/Git/DayBalance/venv/lib/python3.8/site-packages/flask/app.py:1891]
Traceback (most recent call last):
  File "/home/bladner/Git/DayBalance/venv/lib/python3.8/site-packages/flask/app.py", line 2447, in wsgi_app
    response = self.full_dispatch_request()
  File "/home/bladner/Git/DayBalance/venv/lib/python3.8/site-packages/flask/app.py", line 1952, in full_dispatch_request
    rv = self.handle_user_exception(e)
  File "/home/bladner/Git/DayBalance/venv/lib/python3.8/site-packages/flask/app.py", line 1821, in handle_user_exception
    reraise(exc_type, exc_value, tb)
  File "/home/bladner/Git/DayBalance/venv/lib/python3.8/site-packages/flask/_compat.py", line 39, in reraise
    raise value
  File "/home/bladner/Git/DayBalance/venv/lib/python3.8/site-packages/flask/app.py", line 1950, in full_dispatch_request
    rv = self.dispatch_request()
  File "/home/bladner/Git/DayBalance/venv/lib/python3.8/site-packages/flask/app.py", line 1936, in dispatch_request
    return self.view_functions[rule.endpoint](**req.view_args)
  File "/home/bladner/Git/DayBalance/venv/lib/python3.8/site-packages/flask_login/utils.py", line 270, in decorated_view
    elif not current_user.is_authenticated:
  File "/home/bladner/Git/DayBalance/venv/lib/python3.8/site-packages/werkzeug/local.py", line 347, in __getattr__
    return getattr(self._get_current_object(), name)
  File "/home/bladner/Git/DayBalance/venv/lib/python3.8/site-packages/werkzeug/local.py", line 306, in _get_current_object
    return self.__local()
  File "/home/bladner/Git/DayBalance/venv/lib/python3.8/site-packages/flask_login/utils.py", line 26, in <lambda>
    current_user = LocalProxy(lambda: _get_user())
  File "/home/bladner/Git/DayBalance/venv/lib/python3.8/site-packages/flask_login/utils.py", line 346, in _get_user
    current_app.login_manager._load_user()
  File "/home/bladner/Git/DayBalance/venv/lib/python3.8/site-packages/flask_login/login_manager.py", line 302, in _load_user
    raise Exception(
Exception: Missing user_loader or request_loader. Refer to http://flask-login.readthedocs.io/#how-it-works for more info.
2021-04-11 10:17:08,403 ERROR: Exception on /register [GET] [in /home/bladner/Git/DayBalance/venv/lib/python3.8/site-packages/flask/app.py:1891]
Traceback (most recent call last):
  File "/home/bladner/Git/DayBalance/venv/lib/python3.8/site-packages/flask/app.py", line 2447, in wsgi_app
    response = self.full_dispatch_request()
  File "/home/bladner/Git/DayBalance/venv/lib/python3.8/site-packages/flask/app.py", line 1952, in full_dispatch_request
    rv = self.handle_user_exception(e)
  File "/home/bladner/Git/DayBalance/venv/lib/python3.8/site-packages/flask/app.py", line 1821, in handle_user_exception
    reraise(exc_type, exc_value, tb)
  File "/home/bladner/Git/DayBalance/venv/lib/python3.8/site-packages/flask/_compat.py", line 39, in reraise
    raise value
  File "/home/bladner/Git/DayBalance/venv/lib/python3.8/site-packages/flask/app.py", line 1950, in full_dispatch_request
    rv = self.dispatch_request()
  File "/home/bladner/Git/DayBalance/venv/lib/python3.8/site-packages/flask/app.py", line 1936, in dispatch_request
    return self.view_functions[rule.endpoint](**req.view_args)
  File "/home/bladner/Git/DayBalance/app/routes.py", line 203, in register
    if current_user.is_authenticated:
  File "/home/bladner/Git/DayBalance/venv/lib/python3.8/site-packages/werkzeug/local.py", line 347, in __getattr__
    return getattr(self._get_current_object(), name)
  File "/home/bladner/Git/DayBalance/venv/lib/python3.8/site-packages/werkzeug/local.py", line 306, in _get_current_object
    return self.__local()
  File "/home/bladner/Git/DayBalance/venv/lib/python3.8/site-packages/flask_login/utils.py", line 26, in <lambda>
    current_user = LocalProxy(lambda: _get_user())
  File "/home/bladner/Git/DayBalance/venv/lib/python3.8/site-packages/flask_login/utils.py", line 346, in _get_user
    current_app.login_manager._load_user()
  File "/home/bladner/Git/DayBalance/venv/lib/python3.8/site-packages/flask_login/login_manager.py", line 302, in _load_user
    raise Exception(
Exception: Missing user_loader or request_loader. Refer to http://flask-login.readthedocs.io/#how-it-works for more info.
2021-04-11 10:25:50,398 INFO: DayBalance startup [in /home/bladner/Git/DayBalance/app/__init__.py:31]
2021-04-11 10:25:58,504 ERROR: Exception on /register [GET] [in /home/bladner/Git/DayBalance/venv/lib/python3.8/site-packages/flask/app.py:1891]
Traceback (most recent call last):
  File "/home/bladner/Git/DayBalance/venv/lib/python3.8/site-packages/flask/app.py", line 2447, in wsgi_app
    response = self.full_dispatch_request()
  File "/home/bladner/Git/DayBalance/venv/lib/python3.8/site-packages/flask/app.py", line 1952, in full_dispatch_request
    rv = self.handle_user_exception(e)
  File "/home/bladner/Git/DayBalance/venv/lib/python3.8/site-packages/flask/app.py", line 1821, in handle_user_exception
    reraise(exc_type, exc_value, tb)
  File "/home/bladner/Git/DayBalance/venv/lib/python3.8/site-packages/flask/_compat.py", line 39, in reraise
    raise value
  File "/home/bladner/Git/DayBalance/venv/lib/python3.8/site-packages/flask/app.py", line 1950, in full_dispatch_request
    rv = self.dispatch_request()
  File "/home/bladner/Git/DayBalance/venv/lib/python3.8/site-packages/flask/app.py", line 1936, in dispatch_request
    return self.view_functions[rule.endpoint](**req.view_args)
  File "/home/bladner/Git/DayBalance/app/routes.py", line 229, in register
    return render_template('register.html', title=_('Register'), form=form)
NameError: name '_' is not defined
2021-04-11 10:26:50,236 INFO: DayBalance startup [in /home/bladner/Git/DayBalance/app/__init__.py:31]
