2021-04-11 11:29:17,361 ERROR: Exception on /add [GET] [in /home/bladner/Git/DayBalance/venv/lib/python3.8/site-packages/flask/app.py:1891]
Traceback (most recent call last):
  File "/home/bladner/Git/DayBalance/venv/lib/python3.8/site-packages/flask/app.py", line 2447, in wsgi_app
    response = self.full_dispatch_request()
  File "/home/bladner/Git/DayBalance/venv/lib/python3.8/site-packages/flask/app.py", line 1952, in full_dispatch_request
    rv = self.handle_user_exception(e)
  File "/home/bladner/Git/DayBalance/venv/lib/python3.8/site-packages/flask/app.py", line 1821, in handle_user_exception
    reraise(exc_type, exc_value, tb)
  File "/home/bladner/Git/DayBalance/venv/lib/python3.8/site-packages/flask/_compat.py", line 39, in reraise
    raise value
  File "/home/bladner/Git/DayBalance/venv/lib/python3.8/site-packages/flask/app.py", line 1950, in full_dispatch_request
    rv = self.dispatch_request()
  File "/home/bladner/Git/DayBalance/venv/lib/python3.8/site-packages/flask/app.py", line 1936, in dispatch_request
    return self.view_functions[rule.endpoint](**req.view_args)
  File "/home/bladner/Git/DayBalance/venv/lib/python3.8/site-packages/flask_login/utils.py", line 272, in decorated_view
    return func(*args, **kwargs)
  File "/home/bladner/Git/DayBalance/app/routes.py", line 56, in add_transaction
    @app.route("/edit/<int:transaction_id>", methods=["GET", "POST"])
  File "/home/bladner/Git/DayBalance/venv/lib/python3.8/site-packages/flask/templating.py", line 137, in render_template
    return _render(
  File "/home/bladner/Git/DayBalance/venv/lib/python3.8/site-packages/flask/templating.py", line 120, in _render
    rv = template.render(context)
  File "/home/bladner/Git/DayBalance/venv/lib/python3.8/site-packages/jinja2/environment.py", line 1090, in render
    self.environment.handle_exception()
  File "/home/bladner/Git/DayBalance/venv/lib/python3.8/site-packages/jinja2/environment.py", line 832, in handle_exception
    reraise(*rewrite_traceback_stack(source=source))
  File "/home/bladner/Git/DayBalance/venv/lib/python3.8/site-packages/jinja2/_compat.py", line 28, in reraise
    raise value.with_traceback(tb)
  File "/home/bladner/Git/DayBalance/app/templates/transaction.html", line 2, in top-level template code
    {% import 'bootstrap/wtf.html' as wtf %}
  File "/home/bladner/Git/DayBalance/app/templates/base.html", line 1, in top-level template code
    {% extends 'bootstrap/base.html' %}
  File "/home/bladner/Git/DayBalance/venv/lib/python3.8/site-packages/flask_bootstrap/templates/bootstrap/base.html", line 1, in top-level template code
    {% block doc -%}
  File "/home/bladner/Git/DayBalance/venv/lib/python3.8/site-packages/flask_bootstrap/templates/bootstrap/base.html", line 4, in block "doc"
    {%- block html %}
  File "/home/bladner/Git/DayBalance/venv/lib/python3.8/site-packages/flask_bootstrap/templates/bootstrap/base.html", line 20, in block "html"
    {% block body -%}
  File "/home/bladner/Git/DayBalance/venv/lib/python3.8/site-packages/flask_bootstrap/templates/bootstrap/base.html", line 23, in block "body"
    {% block content -%}
  File "/home/bladner/Git/DayBalance/app/templates/base.html", line 46, in block "content"
    {% block app_content %}{% endblock %}
  File "/home/bladner/Git/DayBalance/app/templates/transaction.html", line 8, in block "app_content"
    {{ wtf.quick_form(form) }}
  File "/home/bladner/Git/DayBalance/venv/lib/python3.8/site-packages/jinja2/runtime.py", line 679, in _invoke
    rv = self._func(*arguments)
  File "/home/bladner/Git/DayBalance/venv/lib/python3.8/site-packages/flask_bootstrap/templates/bootstrap/wtf.html", line 200, in template
    {{ form.hidden_tag() }}
  File "/home/bladner/Git/DayBalance/venv/lib/python3.8/site-packages/jinja2/environment.py", line 471, in getattr
    return getattr(obj, attribute)
jinja2.exceptions.UndefinedError: 'form' is undefined
2021-04-11 12:43:42,125 INFO: DayBalance startup [in /home/bladner/Git/DayBalance/app/__init__.py:31]
2021-04-11 12:46:56,033 INFO: DayBalance startup [in /home/bladner/Git/DayBalance/app/__init__.py:31]
2021-04-11 12:47:48,506 INFO: DayBalance startup [in /home/bladner/Git/DayBalance/app/__init__.py:31]
2021-04-11 12:51:52,967 INFO: DayBalance startup [in /home/bladner/Git/DayBalance/app/__init__.py:31]
2021-04-11 12:51:58,634 ERROR: Exception on /add [GET] [in /home/bladner/Git/DayBalance/venv/lib/python3.8/site-packages/flask/app.py:1891]
Traceback (most recent call last):
  File "/home/bladner/Git/DayBalance/venv/lib/python3.8/site-packages/flask/app.py", line 2447, in wsgi_app
    response = self.full_dispatch_request()
  File "/home/bladner/Git/DayBalance/venv/lib/python3.8/site-packages/flask/app.py", line 1952, in full_dispatch_request
    rv = self.handle_user_exception(e)
  File "/home/bladner/Git/DayBalance/venv/lib/python3.8/site-packages/flask/app.py", line 1821, in handle_user_exception
    reraise(exc_type, exc_value, tb)
  File "/home/bladner/Git/DayBalance/venv/lib/python3.8/site-packages/flask/_compat.py", line 39, in reraise
    raise value
  File "/home/bladner/Git/DayBalance/venv/lib/python3.8/site-packages/flask/app.py", line 1950, in full_dispatch_request
    rv = self.dispatch_request()
  File "/home/bladner/Git/DayBalance/venv/lib/python3.8/site-packages/flask/app.py", line 1936, in dispatch_request
    return self.view_functions[rule.endpoint](**req.view_args)
  File "/home/bladner/Git/DayBalance/venv/lib/python3.8/site-packages/flask_login/utils.py", line 272, in decorated_view
    return func(*args, **kwargs)
  File "/home/bladner/Git/DayBalance/app/routes.py", line 13, in add_transaction
    form = TransactionForm("Add Transaction")
  File "/home/bladner/Git/DayBalance/venv/lib/python3.8/site-packages/wtforms/form.py", line 208, in __call__
    return type.__call__(cls, *args, **kwargs)
  File "/home/bladner/Git/DayBalance/app/forms.py", line 44, in __init__
    super(EditProfileForm, self).__init__(*args, **kwargs)
NameError: name 'EditProfileForm' is not defined
2021-04-11 12:52:29,176 INFO: DayBalance startup [in /home/bladner/Git/DayBalance/app/__init__.py:31]
2021-04-11 12:52:44,896 ERROR: Exception on /add [POST] [in /home/bladner/Git/DayBalance/venv/lib/python3.8/site-packages/flask/app.py:1891]
Traceback (most recent call last):
  File "/home/bladner/Git/DayBalance/venv/lib/python3.8/site-packages/flask/app.py", line 2447, in wsgi_app
    response = self.full_dispatch_request()
  File "/home/bladner/Git/DayBalance/venv/lib/python3.8/site-packages/flask/app.py", line 1952, in full_dispatch_request
    rv = self.handle_user_exception(e)
  File "/home/bladner/Git/DayBalance/venv/lib/python3.8/site-packages/flask/app.py", line 1821, in handle_user_exception
    reraise(exc_type, exc_value, tb)
  File "/home/bladner/Git/DayBalance/venv/lib/python3.8/site-packages/flask/_compat.py", line 39, in reraise
    raise value
  File "/home/bladner/Git/DayBalance/venv/lib/python3.8/site-packages/flask/app.py", line 1950, in full_dispatch_request
    rv = self.dispatch_request()
  File "/home/bladner/Git/DayBalance/venv/lib/python3.8/site-packages/flask/app.py", line 1936, in dispatch_request
    return self.view_functions[rule.endpoint](**req.view_args)
  File "/home/bladner/Git/DayBalance/venv/lib/python3.8/site-packages/flask_login/utils.py", line 272, in decorated_view
    return func(*args, **kwargs)
  File "/home/bladner/Git/DayBalance/app/routes.py", line 16, in add_transaction
    user_id=row.id,
NameError: name 'row' is not defined
2021-04-11 12:53:47,242 ERROR: Exception on /edit [GET] [in /home/bladner/Git/DayBalance/venv/lib/python3.8/site-packages/flask/app.py:1891]
Traceback (most recent call last):
  File "/home/bladner/Git/DayBalance/venv/lib/python3.8/site-packages/flask/app.py", line 2447, in wsgi_app
    response = self.full_dispatch_request()
  File "/home/bladner/Git/DayBalance/venv/lib/python3.8/site-packages/flask/app.py", line 1952, in full_dispatch_request
    rv = self.handle_user_exception(e)
  File "/home/bladner/Git/DayBalance/venv/lib/python3.8/site-packages/flask/app.py", line 1821, in handle_user_exception
    reraise(exc_type, exc_value, tb)
  File "/home/bladner/Git/DayBalance/venv/lib/python3.8/site-packages/flask/_compat.py", line 39, in reraise
    raise value
  File "/home/bladner/Git/DayBalance/venv/lib/python3.8/site-packages/flask/app.py", line 1950, in full_dispatch_request
    rv = self.dispatch_request()
  File "/home/bladner/Git/DayBalance/venv/lib/python3.8/site-packages/flask/app.py", line 1936, in dispatch_request
    return self.view_functions[rule.endpoint](**req.view_args)
  File "/home/bladner/Git/DayBalance/venv/lib/python3.8/site-packages/flask_login/utils.py", line 272, in decorated_view
    return func(*args, **kwargs)
TypeError: edit_transaction() missing 1 required positional argument: 'transaction_id'
