2021-04-11 10:32:19,759 ERROR: Exception on /login [GET] [in /home/bladner/Git/DayBalance/venv/lib/python3.8/site-packages/flask/app.py:1891]
Traceback (most recent call last):
  File "/home/bladner/Git/DayBalance/venv/lib/python3.8/site-packages/flask/app.py", line 2447, in wsgi_app
    response = self.full_dispatch_request()
  File "/home/bladner/Git/DayBalance/venv/lib/python3.8/site-packages/flask/app.py", line 1952, in full_dispatch_request
    rv = self.handle_user_exception(e)
  File "/home/bladner/Git/DayBalance/venv/lib/python3.8/site-packages/flask/app.py", line 1821, in handle_user_exception
    reraise(exc_type, exc_value, tb)
  File "/home/bladner/Git/DayBalance/venv/lib/python3.8/site-packages/flask/_compat.py", line 39, in reraise
    raise value
  File "/home/bladner/Git/DayBalance/venv/lib/python3.8/site-packages/flask/app.py", line 1950, in full_dispatch_request
    rv = self.dispatch_request()
  File "/home/bladner/Git/DayBalance/venv/lib/python3.8/site-packages/flask/app.py", line 1936, in dispatch_request
    return self.view_functions[rule.endpoint](**req.view_args)
  File "/home/bladner/Git/DayBalance/app/routes.py", line 192, in login
    return render_template('login.html', title='Sign In', form=form)
  File "/home/bladner/Git/DayBalance/venv/lib/python3.8/site-packages/flask/templating.py", line 137, in render_template
    return _render(
  File "/home/bladner/Git/DayBalance/venv/lib/python3.8/site-packages/flask/templating.py", line 120, in _render
    rv = template.render(context)
  File "/home/bladner/Git/DayBalance/venv/lib/python3.8/site-packages/jinja2/environment.py", line 1090, in render
    self.environment.handle_exception()
  File "/home/bladner/Git/DayBalance/venv/lib/python3.8/site-packages/jinja2/environment.py", line 832, in handle_exception
    reraise(*rewrite_traceback_stack(source=source))
  File "/home/bladner/Git/DayBalance/venv/lib/python3.8/site-packages/jinja2/_compat.py", line 28, in reraise
    raise value.with_traceback(tb)
  File "/home/bladner/Git/DayBalance/app/templates/login.html", line 2, in top-level template code
    {% import 'bootstrap/wtf.html' as wtf %}
  File "/home/bladner/Git/DayBalance/app/templates/base.html", line 1, in top-level template code
    {% extends 'bootstrap/base.html' %}
  File "/home/bladner/Git/DayBalance/venv/lib/python3.8/site-packages/flask_bootstrap/templates/bootstrap/base.html", line 1, in top-level template code
    {% block doc -%}
  File "/home/bladner/Git/DayBalance/venv/lib/python3.8/site-packages/flask_bootstrap/templates/bootstrap/base.html", line 4, in block "doc"
    {%- block html %}
  File "/home/bladner/Git/DayBalance/venv/lib/python3.8/site-packages/flask_bootstrap/templates/bootstrap/base.html", line 20, in block "html"
    {% block body -%}
  File "/home/bladner/Git/DayBalance/venv/lib/python3.8/site-packages/flask_bootstrap/templates/bootstrap/base.html", line 23, in block "body"
    {% block content -%}
  File "/home/bladner/Git/DayBalance/app/templates/base.html", line 46, in block "content"
    {% block app_content %}{% endblock %}
  File "/home/bladner/Git/DayBalance/app/templates/login.html", line 5, in block "app_content"
    <h1>{{ _('Sign In') }}</h1>
jinja2.exceptions.UndefinedError: '_' is undefined
2021-04-11 10:32:50,567 INFO: DayBalance startup [in /home/bladner/Git/DayBalance/app/__init__.py:31]
2021-04-11 11:02:06,495 INFO: DayBalance startup [in /home/bladner/Git/DayBalance/app/__init__.py:31]
2021-04-11 11:05:05,880 INFO: DayBalance startup [in /home/bladner/Git/DayBalance/app/__init__.py:31]
2021-04-11 11:10:10,356 INFO: DayBalance startup [in /home/bladner/Git/DayBalance/app/__init__.py:31]
2021-04-11 11:10:20,026 INFO: DayBalance startup [in /home/bladner/Git/DayBalance/app/__init__.py:31]
2021-04-11 11:10:38,190 INFO: DayBalance startup [in /home/bladner/Git/DayBalance/app/__init__.py:31]
2021-04-11 11:11:48,584 INFO: DayBalance startup [in /home/bladner/Git/DayBalance/app/__init__.py:31]
2021-04-11 11:19:40,942 INFO: DayBalance startup [in /home/bladner/Git/DayBalance/app/__init__.py:31]
2021-04-11 11:20:19,250 ERROR: Exception on /register [POST] [in /home/bladner/Git/DayBalance/venv/lib/python3.8/site-packages/flask/app.py:1891]
Traceback (most recent call last):
  File "/home/bladner/Git/DayBalance/venv/lib/python3.8/site-packages/flask/app.py", line 2447, in wsgi_app
    response = self.full_dispatch_request()
  File "/home/bladner/Git/DayBalance/venv/lib/python3.8/site-packages/flask/app.py", line 1952, in full_dispatch_request
    rv = self.handle_user_exception(e)
  File "/home/bladner/Git/DayBalance/venv/lib/python3.8/site-packages/flask/app.py", line 1821, in handle_user_exception
    reraise(exc_type, exc_value, tb)
  File "/home/bladner/Git/DayBalance/venv/lib/python3.8/site-packages/flask/_compat.py", line 39, in reraise
    raise value
  File "/home/bladner/Git/DayBalance/venv/lib/python3.8/site-packages/flask/app.py", line 1950, in full_dispatch_request
    rv = self.dispatch_request()
  File "/home/bladner/Git/DayBalance/venv/lib/python3.8/site-packages/flask/app.py", line 1936, in dispatch_request
    return self.view_functions[rule.endpoint](**req.view_args)
  File "/home/bladner/Git/DayBalance/app/routes.py", line 216, in register
    user_id=row.id,
NameError: name 'row' is not defined
2021-04-11 11:21:44,251 INFO: DayBalance startup [in /home/bladner/Git/DayBalance/app/__init__.py:31]
