2021-04-11 20:17:00,701 ERROR: Exception on /edit/1 [GET] [in /home/bladner/Git/DayBalance/venv/lib/python3.8/site-packages/flask/app.py:1891]
Traceback (most recent call last):
  File "/home/bladner/Git/DayBalance/venv/lib/python3.8/site-packages/flask/app.py", line 2447, in wsgi_app
    response = self.full_dispatch_request()
  File "/home/bladner/Git/DayBalance/venv/lib/python3.8/site-packages/flask/app.py", line 1952, in full_dispatch_request
    rv = self.handle_user_exception(e)
  File "/home/bladner/Git/DayBalance/venv/lib/python3.8/site-packages/flask/app.py", line 1821, in handle_user_exception
    reraise(exc_type, exc_value, tb)
  File "/home/bladner/Git/DayBalance/venv/lib/python3.8/site-packages/flask/_compat.py", line 39, in reraise
    raise value
  File "/home/bladner/Git/DayBalance/venv/lib/python3.8/site-packages/flask/app.py", line 1950, in full_dispatch_request
    rv = self.dispatch_request()
  File "/home/bladner/Git/DayBalance/venv/lib/python3.8/site-packages/flask/app.py", line 1936, in dispatch_request
    return self.view_functions[rule.endpoint](**req.view_args)
  File "/home/bladner/Git/DayBalance/venv/lib/python3.8/site-packages/flask_login/utils.py", line 272, in decorated_view
    return func(*args, **kwargs)
  File "/home/bladner/Git/DayBalance/app/main/routes.py", line 105, in edit_transaction
    return render_template('edit_transaction.html', title='Edit Transaction', form=form, transaction_id=edited_transaction.id)
  File "/home/bladner/Git/DayBalance/venv/lib/python3.8/site-packages/flask/templating.py", line 137, in render_template
    return _render(
  File "/home/bladner/Git/DayBalance/venv/lib/python3.8/site-packages/flask/templating.py", line 120, in _render
    rv = template.render(context)
  File "/home/bladner/Git/DayBalance/venv/lib/python3.8/site-packages/jinja2/environment.py", line 1090, in render
    self.environment.handle_exception()
  File "/home/bladner/Git/DayBalance/venv/lib/python3.8/site-packages/jinja2/environment.py", line 832, in handle_exception
    reraise(*rewrite_traceback_stack(source=source))
  File "/home/bladner/Git/DayBalance/venv/lib/python3.8/site-packages/jinja2/_compat.py", line 28, in reraise
    raise value.with_traceback(tb)
  File "/home/bladner/Git/DayBalance/app/templates/edit_transaction.html", line 2, in top-level template code
    {% import 'bootstrap/wtf.html' as wtf %}
  File "/home/bladner/Git/DayBalance/app/templates/base.html", line 1, in top-level template code
    {% extends 'bootstrap/base.html' %}
  File "/home/bladner/Git/DayBalance/venv/lib/python3.8/site-packages/flask_bootstrap/templates/bootstrap/base.html", line 1, in top-level template code
    {% block doc -%}
  File "/home/bladner/Git/DayBalance/venv/lib/python3.8/site-packages/flask_bootstrap/templates/bootstrap/base.html", line 4, in block "doc"
    {%- block html %}
  File "/home/bladner/Git/DayBalance/venv/lib/python3.8/site-packages/flask_bootstrap/templates/bootstrap/base.html", line 20, in block "html"
    {% block body -%}
  File "/home/bladner/Git/DayBalance/venv/lib/python3.8/site-packages/flask_bootstrap/templates/bootstrap/base.html", line 23, in block "body"
    {% block content -%}
  File "/home/bladner/Git/DayBalance/app/templates/base.html", line 56, in block "content"
    {% block app_content %}{% endblock %}
  File "/home/bladner/Git/DayBalance/app/templates/edit_transaction.html", line 14, in block "app_content"
    <a href="{{ url_for('index') }}">Cancel</a>
  File "/home/bladner/Git/DayBalance/venv/lib/python3.8/site-packages/flask/helpers.py", line 370, in url_for
    return appctx.app.handle_url_build_error(error, endpoint, values)
  File "/home/bladner/Git/DayBalance/venv/lib/python3.8/site-packages/flask/app.py", line 2216, in handle_url_build_error
    reraise(exc_type, exc_value, tb)
  File "/home/bladner/Git/DayBalance/venv/lib/python3.8/site-packages/flask/_compat.py", line 39, in reraise
    raise value
  File "/home/bladner/Git/DayBalance/venv/lib/python3.8/site-packages/flask/helpers.py", line 357, in url_for
    rv = url_adapter.build(
  File "/home/bladner/Git/DayBalance/venv/lib/python3.8/site-packages/werkzeug/routing.py", line 2179, in build
    raise BuildError(endpoint, values, method, self)
werkzeug.routing.BuildError: Could not build url for endpoint 'index'. Did you mean 'main.index' instead?
2021-04-11 20:17:54,274 INFO: DayBalance startup [in /home/bladner/Git/DayBalance/app/__init__.py:72]
2021-04-11 20:18:09,966 ERROR: Exception on /delete/2 [GET] [in /home/bladner/Git/DayBalance/venv/lib/python3.8/site-packages/flask/app.py:1891]
Traceback (most recent call last):
  File "/home/bladner/Git/DayBalance/venv/lib/python3.8/site-packages/flask/app.py", line 2447, in wsgi_app
    response = self.full_dispatch_request()
  File "/home/bladner/Git/DayBalance/venv/lib/python3.8/site-packages/flask/app.py", line 1952, in full_dispatch_request
    rv = self.handle_user_exception(e)
  File "/home/bladner/Git/DayBalance/venv/lib/python3.8/site-packages/flask/app.py", line 1821, in handle_user_exception
    reraise(exc_type, exc_value, tb)
  File "/home/bladner/Git/DayBalance/venv/lib/python3.8/site-packages/flask/_compat.py", line 39, in reraise
    raise value
  File "/home/bladner/Git/DayBalance/venv/lib/python3.8/site-packages/flask/app.py", line 1950, in full_dispatch_request
    rv = self.dispatch_request()
  File "/home/bladner/Git/DayBalance/venv/lib/python3.8/site-packages/flask/app.py", line 1936, in dispatch_request
    return self.view_functions[rule.endpoint](**req.view_args)
  File "/home/bladner/Git/DayBalance/venv/lib/python3.8/site-packages/flask_login/utils.py", line 272, in decorated_view
    return func(*args, **kwargs)
  File "/home/bladner/Git/DayBalance/app/main/routes.py", line 118, in delete_transaction
    return redirect(url_for('index'))
  File "/home/bladner/Git/DayBalance/venv/lib/python3.8/site-packages/flask/helpers.py", line 370, in url_for
    return appctx.app.handle_url_build_error(error, endpoint, values)
  File "/home/bladner/Git/DayBalance/venv/lib/python3.8/site-packages/flask/app.py", line 2216, in handle_url_build_error
    reraise(exc_type, exc_value, tb)
  File "/home/bladner/Git/DayBalance/venv/lib/python3.8/site-packages/flask/_compat.py", line 39, in reraise
    raise value
  File "/home/bladner/Git/DayBalance/venv/lib/python3.8/site-packages/flask/helpers.py", line 357, in url_for
    rv = url_adapter.build(
  File "/home/bladner/Git/DayBalance/venv/lib/python3.8/site-packages/werkzeug/routing.py", line 2179, in build
    raise BuildError(endpoint, values, method, self)
werkzeug.routing.BuildError: Could not build url for endpoint 'index'. Did you mean 'main.index' instead?
2021-04-11 20:19:24,414 INFO: DayBalance startup [in /home/bladner/Git/DayBalance/app/__init__.py:72]
2021-04-11 20:19:28,102 ERROR: Exception on /edit/2 [GET] [in /home/bladner/Git/DayBalance/venv/lib/python3.8/site-packages/flask/app.py:1891]
Traceback (most recent call last):
  File "/home/bladner/Git/DayBalance/venv/lib/python3.8/site-packages/flask/app.py", line 2447, in wsgi_app
    response = self.full_dispatch_request()
  File "/home/bladner/Git/DayBalance/venv/lib/python3.8/site-packages/flask/app.py", line 1952, in full_dispatch_request
    rv = self.handle_user_exception(e)
  File "/home/bladner/Git/DayBalance/venv/lib/python3.8/site-packages/flask/app.py", line 1821, in handle_user_exception
    reraise(exc_type, exc_value, tb)
  File "/home/bladner/Git/DayBalance/venv/lib/python3.8/site-packages/flask/_compat.py", line 39, in reraise
    raise value
  File "/home/bladner/Git/DayBalance/venv/lib/python3.8/site-packages/flask/app.py", line 1950, in full_dispatch_request
    rv = self.dispatch_request()
  File "/home/bladner/Git/DayBalance/venv/lib/python3.8/site-packages/flask/app.py", line 1936, in dispatch_request
    return self.view_functions[rule.endpoint](**req.view_args)
  File "/home/bladner/Git/DayBalance/venv/lib/python3.8/site-packages/flask_login/utils.py", line 272, in decorated_view
    return func(*args, **kwargs)
  File "/home/bladner/Git/DayBalance/app/main/routes.py", line 89, in edit_transaction
    edited_transaction = Transaction.query.filter_by(id=transaction_id).one()
  File "/home/bladner/Git/DayBalance/venv/lib/python3.8/site-packages/sqlalchemy/orm/query.py", line 2782, in one
    return self._iter().one()
  File "/home/bladner/Git/DayBalance/venv/lib/python3.8/site-packages/sqlalchemy/engine/result.py", line 1380, in one
    return self._only_one_row(True, True, False)
  File "/home/bladner/Git/DayBalance/venv/lib/python3.8/site-packages/sqlalchemy/engine/result.py", line 569, in _only_one_row
    raise exc.NoResultFound(
sqlalchemy.exc.NoResultFound: No row was found when one was required
